Workbook

Sheet dados_coletados
A1: INSTITUIÇÃO DE ENSINO | B1: TURNO | C1: CURSO NA INTITUIÇÃO | D1: GRAU | E1: SÉRIE | F1: TURMA | G1: MATRÍCULA | H1: CARTÃO | I1: NOME | J1: NASCIMENTO | K1: CPF | L1: RG | M1: EXPEDIDOR | N1: EXPEDIÇÃO | O1: SEXO | P1: TELEFONE | Q1: CELULAR | R1: EMAIL | S1: CEP | T1: ENDERECO | U1: COMPLEMENTO | V1: NÚMERO | W1: BAIRRO | X1: CIDADE | Y1: UF | Z1: MÃE | AA1: PAI | AB1: APTO | AC1: CADASTRADO | AD1: ALTERDADO | AE1: BLOQUEIO | AF1: BLOQUEADO
A2: 7381 .::. U.I. PROFª NADIR NASCIMENTO MORAES | B2: Vespertino | C2: 41 .::. FUNDAMENTAL II (6º AO 9º ANO) | D2: 1º grau | E2: 6 ANO | I2: Adrian Carlos da Silva Castro | J2: 41210 | K2: 62401535322 | L2: 586116220160 | M2: SSP MA | N2: 42471 | O2: Masculino | Q2: (98) 9 9613 7804 | S2: 65.130-000 | T2: AVENIDA JOSE BUHOFER | U2: AVENIDA | V2: 10 | W2: VILA NAZARE | X2: 2351 .::. Paço do Lumiar | Y2: MA | Z2: Carliana Lima da Silva | AA2: Allan Dias de Castro | AB2: Sim | AC2: 45566.684 | AD2: 45566.684
A3: 7381 .::. U.I. PROFª NADIR NASCIMENTO MORAES | B3: Matutino | C3: 40 .::. FUNDAMENTAL I (1º AO 5º ANO) | D3: 1º grau | E3: 3 ANO | I3: Agatha Cristina da Silva Feitosa | J3: 42441 | K3: 63622510323 | O3: Feminino | Q3: (98) 9 8151 3038 | S3: 65.130-000 | T3: RUA A | U3: CP 38 CS 10 PS 8 | V3: 101 | W3: SITIO NATUREZA | X3: 2351 .::. Paço do Lumiar | Y3: MA | Z3: Andrea Patricia da Silva Estácio | AA3: Franscisco das Chagas Feitosa | AB3: Sim | AC3: 45568.322 | AD3: 45568.322
A4: 7381 .::. U.I. PROFª NADIR NASCIMENTO MORAES | B4: Vespertino | C4: 41 .::. FUNDAMENTAL II (6º AO 9º ANO) | D4: 1º grau | E4: 8 ANO | I4: Alexandre Bastos Pinheiro | J4: 40551 | K4: 62022470370 | L4: 544223920147 | M4: SSP MA | N4: 41940 | O4: Masculino | S4: 65.130-000 | T4: AVENIDA HILTON ROCHA . QUADRA 33 | U4: AVENIDA | V4: 8 | W4: PRESIDENTE VARGAS / MAIOBÃO | X4: 2351 .::. Paço do Lumiar | Y4: MA | Z4: Maria Jose do Nascimento Bastos Pinheiro | AA4: Eduardo dos Santos Pinheiro | AB4: Sim | AC4: 45581.615 | AD4: 45583.308
A5: 7381 .::. U.I. PROFª NADIR NASCIMENTO MORAES | B5: Matutino | C5: 40 .::. FUNDAMENTAL I (1º AO 5º ANO) | D5: 1º grau | E5: 2 ANO | I5: Alexandre Gregory do Rosario Abreu | J5: 42624 | K5: 9507684301 | O5: Masculino | Q5: (98) 9 8702 8832 | S5: 65.110-000 | T5: AVENIDA 02 | U5: AVENIDA | V5: 321 | W5: VILA SARNEY FILHO | X5: 2401 .::. São José de Ribamar | Y5: MA | Z5: Dayse Silva do Rosário Abreu | AA5: Crysthian Gregory Abreu Costa | AB5: Sim | AC5: 45567.353 | AD5: 45567.433
A6: 7381 .::. U.I. PROFª NADIR NASCIMENTO MORAES | B6: Matutino | C6: 40 .::. FUNDAMENTAL I (1º AO 5º ANO) | D6: 1º grau | E6: 5 ANO | I6: Alex Raylan Costa Nogueira | J6: 41576 | K6: 63271129355 | O6: Masculino | S6: 65.130-000 | T6: RUA 10 | U6: QUADRA 19 | V6: 20 | W6: JARDIM SANTA CLARA | X6: 2351 .::. Paço do Lumiar | Y6: MA | Z6: Rafaela Costa do Nascimento | AA6: Adanias Nogueira | AB6: Sim | AC6: 45573.358 | AD6: 45573.358
A7: 7381 .::. U.I. PROFª NADIR NASCIMENTO MORAES | B7: Vespertino | C7: 41 .::. FUNDAMENTAL II (6º AO 9º ANO) | D7: 1º grau | E7: 7 ANO | I7: Alice Asevedo Bittencourt | J7: 40848 | K7: 63208134312 | L7: 678293520182 | M7: SSP MA | N7: 43384 | O7: Feminino | Q7: (98) 9 8422 2542 | S7: 65.130-000 | T7: RUA B QUADRA 14 | U7: RUA | V7: 3 | W7: MAIOBAO | X7: 2351 .::. Paço do Lumiar | Y7: MA | Z7: Catharina Maria Azevedo Chaves | AA7: Marcello Carvalho Bittencourt | AB7: Sim | AC7: 45567.707 | AD7: 45567.707
A8: 7381 .::. U.I. PROFª NADIR NASCIMENTO MORAES | B8: Matutino | C8: 40 .::. FUNDAMENTAL I (1º AO 5º ANO) | D8: 1º grau | E8: 3 ANO | I8: Alice Ferreira Alves | J8: 42229 | K8: 8559046232 | O8: Feminino | Q8: (94) 9 9127 7430 | S8: 65.130-000 | T8: RUA 140 | U8: QUADRA 126 | V8: 20 | W8: MAIOBAO | X8: 2351 .::. Paço do Lumiar | Y8: MA | Z8: Lindalva Silva Ferreira | AA8: Roberto Correia Alves | AB8: Sim | AC8: 45568.324 | AD8: 45568.324
A9: 7381 .::. U.I. PROFª NADIR NASCIMENTO MORAES | B9: Vespertino | C9: 41 .::. FUNDAMENTAL II (6º AO 9º ANO) | D9: 1º grau | E9: 7 ANO | I9: Alvaro Ezequiel de Sousa Machado | J9: 40032 | K9: 62629405370 | L9: 614637320177 | M9: SSP MA | N9: 42790 | O9: Masculino | Q9: (98) 9 8708 0515 | S9: 65.130-000 | T9: AVENIDA DOS COLABORADORES TV 11 QD 11 | U9: AVENIDA | V9: 12 | W9: PRESIDENTE VARGAS | X9: 2351 .::. Paço do Lumiar | Y9: MA | Z9: Anny Karolynny de Sousa Machado | AB9: Sim | AC9: 45567.697 | AD9: 45567.697
A10: 7381 .::. U.I. PROFª NADIR NASCIMENTO MORAES | B10: Vespertino | C10: 41 .::. FUNDAMENTAL II (6º AO 9º ANO) | D10: 1º grau | E10: 9 ANO | F10: B | I10: Amanda Emilly de Sousa Correa | J10: 40253 | K10: 61920925325 | L10: 532571120140 | M10: SSP MA | N10: 41837 | O10: Feminino | Q10: (98) 9 8714 9252 | S10: 65.130-000 | T10: RUA D QUADRA 06 | U10: RUA | V10: 35 | W10: NOVO HORIZONTE | X10: 2351 .::. Paço do Lumiar | Y10: MA | Z10: Aline Figueiredo de Sousa Correa | AA10: Andre Luis de Jesus Correa | AB10: Sim | AC10: 45574.661 | AD10: 45583.322
A11: 7381 .::. U.I. PROFª NADIR NASCIMENTO MORAES | B11: Vespertino | C11: 41 .::. FUNDAMENTAL II (6º AO 9º ANO) | D11: 1º grau | E11: 6 ANO | I11: Ana Allicya Matos Guimaraes da Silva | J11: 41361 | K11: 62270235312 | L11: 570371120153 | M11: SSP MA | N11: 42263 | O11: Feminino | Q11: (98) 9 9122 9995 | S11: 65.130-000 | T11: RUA NOVA | U11: RUA | W11: MAIOBAO | X11: 2351 .::. Paço do Lumiar | Y11: MA | Z11: Lilia Raquel Matos Guimaraes | AA11: Uiron Marcos Everton da Silva | AB11: Sim | AC11: 45566.654 | AD11: 45566.654
A12: 7381 .::. U.I. PROFª NADIR NASCIMENTO MORAES | B12: Vespertino | C12: 41 .::. FUNDAMENTAL II (6º AO 9º ANO) | D12: 1º grau | E12: 9 ANO | F12: A | I12: Ana Beatriz de Sousa Nunes | J12: 40133 | K12: 62929571365 | L12: 647318120181 | M12: SSP MA | N12: 43122 | O12: Feminino | Q12: (98) 9821 7516 | S12: 65.110-000 | T12: RUA VITORIA | U12: RUA | V12: 14 | W12: VILA KIOLA | X12: 2401 .::. São José de Ribamar | Y12: MA | Z12: Carmen Celia Ferreira de Sousa | AA12: Irandir Araujo Nunes | AB12: Sim | AC12: 45573.636 | AD12: 45583.322
A13: 7381 .::. U.I. PROFª NADIR NASCIMENTO MORAES | B13: Matutino | C13: 40 .::. FUNDAMENTAL I (1º AO 5º ANO) | D13: 1º grau | E13: 4 ANO | I13: Ana Beatriz Monteiro Silva | J13: 41905 | K13: 62566981345 | O13: Feminino | S13: 65.130-000 | T13: RUA D | U13: QUADRA 21 | V13: 38 | W13: NOVO HORIZONTE | X13: 2351 .::. Paço do Lumiar | Y13: MA | Z13: Rayanne Elaine Garcez da Silva | AA13: Emanuel Monteiro de Lima | AB13: Sim | AC13: 45568.41 | AD13: 45568.41
A14: 7381 .::. U.I. PROFª NADIR NASCIMENTO MORAES | B14: Vespertino | C14: 41 .::. FUNDAMENTAL II (6º AO 9º ANO) | D14: 1º grau | E14: 9 ANO | F14: A | I14: Anabela Veloso de Brito | J14: 40043 | K14: 62790011303 | L14: 632558820175 | M14: SSP MA | N14: 42984 | O14: Feminino | Q14: (98) 9 8877 9747 | S14: 65.130-000 | T14: RUA QUADRA | U14: RUA | W14: MAIOBAO | X14: 2351 .::. Paço do Lumiar | Y14: MA | Z14: Keila Nunes Veloso | AA14: Hugo Deleon Lima de Brito | AB14: Sim | AC14: 45574.608 | AD14: 45574.608
A15: 7381 .::. U.I. PROFª NADIR NASCIMENTO MORAES | B15: Vespertino | C15: 41 .::. FUNDAMENTAL II (6º AO 9º ANO) | D15: 1º grau | E15: 7 ANO | I15: Ana Caroline Silva Martins | J15: 40926 | K15: 62055718380 | L15: 547704020146 | M15: SSP MA | N15: 41983 | O15: Feminino | Q15: (98) 9 8606 2914 | S15: 65.130-000 | T15: RUA 02 QUADRA 04 | U15: RUA | V15: 8 | W15: SANTA CLARA | X15: 2351 .::. Paço do Lumiar | Y15: MA | Z15: Valdilene Silva Martins | AA15: Harrison Rodrigues Martins | AB15: Sim | AC15: 45568.608 | AD15: 45568.608
A16: 7381 .::. U.I. PROFª NADIR NASCIMENTO MORAES | B16: Vespertino | C16: 41 .::. FUNDAMENTAL II (6º AO 9º ANO) | D16: 1º grau | E16: 9 ANO | F16: A | I16: Ana Carolyne Campos de Sousa | J16: 40203 | K16: 63629069347 | L16: 7291000620200 | M16: SSP MA | N16: 44056 | O16: Feminino | Q16: (98) 9 8612 1604 | S16: 65.130-000 | T16: RUA DA MANGA | U16: RUA | V16: 1 | W16: LIMA VERDE | X16: 2351 .::. Paço do Lumiar | Y16: MA | Z16: Tabda Campos de Sousa | AA16: Eudes de Sousa Viana | AB16: Sim | AC16: 45574.595 | AD16: 45583.322
A17: 7381 .::. U.I. PROFª NADIR NASCIMENTO MORAES | B17: Vespertino | C17: 41 .::. FUNDAMENTAL II (6º AO 9º ANO) | D17: 1º grau | E17: 9 ANO | F17: A | I17: Ana Clara Mendes Costa | J17: 40041 | K17: 62042472395 | L17: 546441920140 | M17: SSP MA | N17: 41967 | O17: Feminino | Q17: (98) 9 9968 3454 | S17: 65.130-000 | T17: TRAVESSA 26 QUADRA 26 | U17: TRAVESSA | V17: 12 | W17: PRESIDENTE VARGAS | X17: 2351 .::. Paço do Lumiar | Y17: MA | Z17: Cleonice de Jesus Mendes Costa | AA17: Josivaldo Gomes Costa | AB17: Sim | AC17: 45574.592 | AD17: 45583.323
A18: 7381 .::. U.I. PROFª NADIR NASCIMENTO MORAES | B18: Vespertino | C18: 41 .::. FUNDAMENTAL II (6º AO 9º ANO) | D18: 1º grau | E18: 9 ANO | F18: A | I18: Ana Emanuelle Ferreira Castro | J18: 40403 | K18: 61268896306 | L18: 467491320123 | M18: SSP MA | N18: 43331 | O18: Feminino | Q18: (98) 9 9616 5597 | S18: 65.130-000 | T18: RUA 02 QUADRA G | U18: RUA | V18: 25 | W18: SARAMANTA II | X18: 2351 .::. Paço do Lumiar | Y18: MA | Z18: Maria Tereza Silva Ferreira Castro | AA18: Manoel Pereira Castro Neto | AB18: Sim | AC18: 45574.622 | AD18: 45583.323
A19: 7381 .::. U.I. PROFª NADIR NASCIMENTO MORAES | B19: Vespertino | C19: 41 .::. FUNDAMENTAL II (6º AO 9º ANO) | D19: 1º grau | E19: 8 ANO | I19: Ana Julia Oliveira Freitas | J19: 40537 | K19: 62047067308 | O19: Feminino | S19: 65.130-000 | T19: AVENIDA 10 | U19: AVENIDA | V19: 29 | W19: VILA NAZARE | X19: 2351 .::. Paço do Lumiar | Y19: MA | Z19: Adriana de Fatima Ferreira de Oliveira | AA19: Jamilson Menezes Freitas | AB19: Sim | AC19: 45581.342 | AD19: 45581.342
A20: 7381 .::. U.I. PROFª NADIR NASCIMENTO MORAES | B20: Vespertino | C20: 41 .::. FUNDAMENTAL II (6º AO 9º ANO) | D20: 1º grau | E20: 9 ANO | F20: B | I20: Ana Julia Rodrigues Araujo | J20: 39995 | K20: 62472360347 | L20: 594872320167 | M20: SSP MA | N20: 42571 | O20: Feminino | S20: 65.130-000 | T20: RUA G QUADRA 20 | U20: RUA | V20: 27 | W20: NOVO HORIZONTE | X20: 2351 .::. Paço do Lumiar | Y20: MA | Z20: Ana Patrícia Rodrigues Araújo | AA20: Julio Morais de Araujo | AB20: Sim | AC20: 45574.631 | AD20: 45583.323
A21: 7381 .::. U.I. PROFª NADIR NASCIMENTO MORAES | B21: Vespertino | C21: 41 .::. FUNDAMENTAL II (6º AO 9º ANO) | D21: 1º grau | E21: 8 ANO | I21: Ana Karina Maciel dos Reis | J21: 40444 | K21: 62050914377 | O21: Feminino | S21: 65.130-000 | T21: RUA PRINCESA ORLEANS | U21: RUA | V21: 23 | W21: VILA KIOLA | X21: 2351 .::. Paço do Lumiar | Y21: MA | Z21: Edvania Feitosa Maciel | AA21: Joao da Cruz Martins dos Reis | AB21: Sim | AC21: 45583.34 | AD21: 45583.34
A22: 7381 .::. U.I. PROFª NADIR NASCIMENTO MORAES | B22: Matutino | C22: 40 .::. FUNDAMENTAL I (1º AO 5º ANO) | D22: 1º grau | E22: 4 ANO | I22: Ana Luiza Ferreira Castro | J22: 41899 | K22: 62535452308 | O22: Feminino | S22: 65.130-000 | T22: RUA 02 | U22: QUADRA G | V22: 25 | W22: SARAMANTA | X22: 2351 .::. Paço do Lumiar | Y22: MA | Z22: Maria Tereza Silva Ferreira Castro | AA22: Manoel Pereira Castro Neto | AB22: Sim | AC22: 45568.418 | AD22: 45568.418
A23: 7381 .::. U.I. PROFª NADIR NASCIMENTO MORAES | B23: Vespertino | C23: 41 .::. FUNDAMENTAL II (6º AO 9º ANO) | D23: 1º grau | E23: 9 ANO | F23: A | I23: Ana Paula Diniz Silva | J23: 40059 | K23: 61733823344 | L23: 513689820147 | M23: SSP MA | N23: 41668 | O23: Feminino | Q23: (98) 9 9231 8062 | S23: 65.130-000 | T23: RUA 03 QUADRA 08 | U23: RUA | V23: 8 | W23: JARDIM PRIMAVERA | X23: 2351 .::. Paço do Lumiar | Y23: MA | Z23: Jozilene Medeiros Diniz | AA23: Paulo Roberto Araujo Silva | AB23: Sim | AC23: 45574.59 | AD23: 45583.323
A24: 7381 .::. U.I. PROFª NADIR NASCIMENTO MORAES | B24: Matutino | C24: 40 .::. FUNDAMENTAL I (1º AO 5º ANO) | D24: 1º grau | E24: 3 ANO | I24: Ana Sara Correia dos Santos | J24: 42446 | K24: 62559759322 | O24: Feminino | S24: 65.130-000 | T24: RUA 133 | U24: QUADRA 130 | V24: 9 | W24: MAIOBAO | X24: 2351 .::. Paço do Lumiar | Y24: MA | Z24: Eronilde da Silva Correia | AA24: Luis Carlos Lima dos Santos | AB24: Sim | AC24: 45568.33 | AD24: 45568.33
A25: 7381 .::. U.I. PROFª NADIR NASCIMENTO MORAES | B25: Vespertino | C25: 41 .::. FUNDAMENTAL II (6º AO 9º ANO) | D25: 1º grau | E25: 9 ANO | F25: A | I25: Ana Sofia Lopes Santos | J25: 40037 | K25: 9378506321 | L25: 4744168 | M25: SSP MA | N25: 43111 | O25: Feminino | Q25: (98) 0000 0000 | S25: 65.110-000 | T25: AVENIDA TRANCREDO NEVES | U25: AVENIDA | W25: VILLAGE DOS BOSQUE II | X25: 2401 .::. São José de Ribamar | Y25: MA | Z25: Wenna Lopes Silva | AA25: Tiago Moraes Lima dos Santos | AB25: Sim | AC25: 45573.634 | AD25: 45573.634
A26: 7381 .::. U.I. PROFª NADIR NASCIMENTO MORAES | B26: Matutino | C26: 40 .::. FUNDAMENTAL I (1º AO 5º ANO) | D26: 1º grau | E26: 5 ANO | I26: André Martins Marques Junior | J26: 41308 | K26: 7599273328 | O26: Masculino | S26: 65.130-000 | T26: RUA I | U26: QUADRA 29 | V26: 23 | W26: SITIO NATUREZA | X26: 2351 .::. Paço do Lumiar | Y26: MA | Z26: Karliany Brito Marques | AA26: André Martins Marques | AB26: Sim | AC26: 45573.36 | AD26: 45573.36
A27: 7381 .::. U.I. PROFª NADIR NASCIMENTO MORAES | B27: Matutino | C27: 40 .::. FUNDAMENTAL I (1º AO 5º ANO) | D27: 1º grau | E27: 4 ANO | I27: Andrés Sanchez Silva Frazao | J27: 42086 | K27: 63304755390 | O27: Masculino | S27: 65.110-000 | T27: TRAVESSA DA ESTRADA DE RIBAMAR | U27: BLOCO 2A | V27: 301 | W27: RECANTO VERDE 4 | X27: 2401 .::. São José de Ribamar | Y27: MA | Z27: Alterlene Oliveira da Silva | AA27: Thales Santos Frazão | AB27: Sim | AC27: 45568.422 | AD27: 45568.422
A28: 7381 .::. U.I. PROFª NADIR NASCIMENTO MORAES | B28: Matutino | C28: 40 .::. FUNDAMENTAL I (1º AO 5º ANO) | D28: 1º grau | E28: 2 ANO | I28: Angélica do Espirito Santo Bezerra | J28: 41828 | K28: 8042737319 | O28: Feminino | Q28: (98) 9 8441 5000 | S28: 65.130-000 | T28: RUA 115 | U28: QUADRA 78 | V28: 16 | W28: MAIOBAO | X28: 2351 .::. Paço do Lumiar | Y28: MA | Z28: Rosilene do Espírito Santo Bezerra | AA28: Josué Alves Bezerra Junior | AB28: Sim | AC28: 45567.358 | AD28: 45567.434
A29: 7381 .::. U.I. PROFª NADIR NASCIMENTO MORAES | B29: Matutino | C29: 40 .::. FUNDAMENTAL I (1º AO 5º ANO) | D29: 1º grau | E29: 4 ANO | I29: Angelo Gabriel Lisboa Santos Amado | J29: 42135 | K29: 8107689330 | O29: Masculino | S29: 65.130-000 | T29: RUA 13 | U29: QUADRA 13 | V29: 20 | W29: RESIDENCIAL SAFIRA | X29: 2351 .::. Paço do Lumiar | Y29: MA | Z29: Geisa Aline Lisboa Santos Amado | AA29: Raimundo José Ferreira Amado | AB29: Sim | AC29: 45568.424 | AD29: 45568.424
A30: 7381 .::. U.I. PROFª NADIR NASCIMENTO MORAES | B30: Matutino | C30: 40 .::. FUNDAMENTAL I (1º AO 5º ANO) | D30: 1º grau | E30: 2 ANO | I30: Anna Leticia Nascimento Castro | J30: 42625 | K30: 63700340370 | O30: Feminino | Q30: (98) 9 8475 0494 | S30: 65.130-000 | T30: TRAVESSA 31 | U30: QUADRA 30 | V30: 15 | W30: MAIOBAO | X30: 2351 .::. Paço do Lumiar | Y30: MA | Z30: Darlen Thalya de Sousa Nascimento | AA30: Eliedson Barbosa Castro | AB30: Sim | AC30: 45567.357 | AD30: 45567.434
A31: 7381 .::. U.I. PROFª NADIR NASCIMENTO MORAES | B31: Vespertino | C31: 41 .::. FUNDAMENTAL II (6º AO 9º ANO) | D31: 1º grau | E31: 7 ANO | I31: Anthony Vitor Martins Lopes | J31: 40973 | K31: 61740709306 | O31: Masculino | Q31: (98) 9 8883 5658 | S31: 65.130-000 | T31: AVENIDA 02 QUADRA 02 | U31: AVENIDA | V31: 22 | W31: NOVO PAÇO | X31: 2351 .::. Paço do Lumiar | Y31: MA | Z31: Ada Rubia Nunes Martins | AA31: Antonio Vitorio Lopes | AB31: Sim | AC31: 45568.644 | AD31: 45568.644
A32: 7381 .::. U.I. PROFª NADIR NASCIMENTO MORAES | B32: Matutino | C32: 40 .::. FUNDAMENTAL I (1º AO 5º ANO) | D32: 1º grau | E32: 3 ANO | I32: Ariel Benicio Gonçalves Neves | J32: 42406 | K32: 63205105362 | O32: Masculino | S32: 65.130-000 | T32: AVENIDA 10 | U32: QUADRA 107 | V32: 5 | W32: MAIOBAO | X32: 2351 .::. Paço do Lumiar | Y32: MA | Z32: Jhessica Hellen Gonçalves Silva | AA32: Dyeisson Neves Ferreira | AB32: Sim | AC32: 45568.331 | AD32: 45568.331
A33: 7381 .::. U.I. PROFª NADIR NASCIMENTO MORAES | B33: Matutino | C33: 40 .::. FUNDAMENTAL I (1º AO 5º ANO) | D33: 1º grau | E33: 3 ANO | I33: Arthur Sousa Carvalho | J33: 42403 | K33: 62504648324 | O33: Masculino | S33: 65.130-000 | T33: RUA OLHO D`ÃGUA | U33: RUA | V33: 94 | W33: VILA NAZARE | X33: 2351 .::. Paço do Lumiar | Y33: MA | Z33: Celyjane Maruska Santos Sousa | AA33: Jefferson Silberth Silva Carvalho | AB33: Sim | AC33: 45568.333 | AD33: 45568.333
A34: 7381 .::. U.I. PROFª NADIR NASCIMENTO MORAES | B34: Matutino | C34: 40 .::. FUNDAMENTAL I (1º AO 5º ANO) | D34: 1º grau | E34: 4 ANO | I34: Arthur Swagger Vieira Borges | J34: 41652 | K34: 61777029376 | O34: Masculino | S34: 65.130-000 | T34: RUA DOS SABIÃS | U34: QUADRA 04 | V34: 44 | W34: RESIDENCIAL ENCONTRO DAS AVES -SITIO GRANDE | X34: 2351 .::. Paço do Lumiar | Y34: MA | Z34: Samira Kerli Costa Vieira | AA34: Norberto Silva Borges Junior | AB34: Sim | AC34: 45568.451 | AD34: 45568.451
A35: 7381 .::. U.I. PROFª NADIR NASCIMENTO MORAES | B35: Vespertino | C35: 41 .::. FUNDAMENTAL II (6º AO 9º ANO) | D35: 1º grau | E35: 8 ANO | I35: Arthur Vinicius Sousa Muniz | J35: 40280 | K35: 7370325377 | L35: 587313230168 | M35: SSP MA | N35: 42489 | O35: Masculino | S35: 65.130-000 | T35: RUA A , QUADRA 02 | U35: RUA | V35: 4 | W35: RESIDENCIAL NOVO HORIZONTE | X35: 2351 .::. Paço do Lumiar | Y35: MA | Z35: Maria Leonice Gomes Sousa | AA35: Romilson Melo Muniz | AB35: Sim | AC35: 45581.618 | AD35: 45583.321
A36: 7381 .::. U.I. PROFª NADIR NASCIMENTO MORAES | B36: Vespertino | C36: 41 .::. FUNDAMENTAL II (6º AO 9º ANO) | D36: 1º grau | E36: 9 ANO | F36: A | I36: Augusto Conte Silva Correa Junior | J36: 40304 | K36: 60872385302 | L36: 426959420116 | M36: SSP MA | N36: 42706 | O36: Masculino | Q36: (98) 9 7007 9616 | S36: 65.130-000 | T36: PLAZA DAS FLORES III | U36: RUA | V36: 55 | W36: MERCÚS | X36: 2351 .::. Paço do Lumiar | Y36: MA | Z36: Rubnelma Melonio Lima | AA36: Augusto Conte Silva Correa | AB36: Sim | AC36: 45574.565 | AD36: 45583.324
A37: 7381 .::. U.I. PROFª NADIR NASCIMENTO MORAES | B37: Matutino | C37: 40 .::. FUNDAMENTAL I (1º AO 5º ANO) | D37: 1º grau | E37: 1 ANO | I37: Aylla Sophia Lisboa Silva | J37: 42974 | K37: 62862119342 | O37: Feminino | P37: (98) 9 8704 6704 | S37: 65.110-000 | T37: AVENIDA 02 | U37: AVENIDA | V37: 81 | W37: VILA SARNEY FILHO | X37: 2401 .::. São José de Ribamar | Y37: MA | Z37: Leuriane Lisboa de Sousa | AA37: Deywison Silva do Rosario | AB37: Sim | AC37: 45567.324 | AD37: 45567.335
A38: 7381 .::. U.I. PROFª NADIR NASCIMENTO MORAES | B38: Matutino | C38: 40 .::. FUNDAMENTAL I (1º AO 5º ANO) | D38: 1º grau | E38: 4 ANO | I38: Barbara Beatriz Santos Moreno da Silva | J38: 41862 | K38: 62065570300 | O38: Feminino | S38: 65.130-000 | T38: RUA 67 | U38: QUADRA 107 | V38: 1 | W38: MAIOBAO | X38: 2351 .::. Paço do Lumiar | Y38: MA | Z38: Jocely Santos Sousa da Silva | AA38: Leandro Moreno da Silva | AB38: Sim | AC38: 45568.452 | AD38: 45568.452
A39: 7381 .::. U.I. PROFª NADIR NASCIMENTO MORAES | B39: Matutino | C39: 40 .::. FUNDAMENTAL I (1º AO 5º ANO) | D39: 1º grau | E39: 4 ANO | I39: Beatriz Silva de Jesus Martins | J39: 42094 | K39: 62452617326 | O39: Feminino | S39: 65.130-000 | T39: RUA 05 | U39: A | V39: 527 | W39: VILA SARNEY FILHO | X39: 2351 .::. Paço do Lumiar | Y39: MA | Z39: Ozilene Silva de Jesus Martins | AA39: Ludernaik Oliveira Martins | AB39: Sim | AC39: 45568.457 | AD39: 45568.457
A40: 7381 .::. U.I. PROFª NADIR NASCIMENTO MORAES | B40: Matutino | C40: 40 .::. FUNDAMENTAL I (1º AO 5º ANO) | D40: 1º grau | E40: 2 ANO | I40: Brenda Emanuelle Gonçalves Alves | J40: 42475 | K40: 63173021380 | O40: Feminino | Q40: (98) 9 8591 7113 | S40: 65.130-000 | T40: RUA 66 QUADRA 150 | U40: AVENIDA 13 | V40: 9 | W40: MAIOBAO | X40: 2351 .::. Paço do Lumiar | Y40: MA | Z40: Raimunda D`Jesus Freitas Gonçalves | AA40: Eduardo Bruno Brito Alves | AB40: Sim | AC40: 45567.362 | AD40: 45567.434
...

Sheet Planilha1
A1: Instituição de ensino: | B1: Turno: | C1: Curso na Intituição: | D1: Grau: | E1: Ano ou Período: | F1: Turma: | G1: Matrícula: | H1: Cartão: | I1: Nome: | J1: Nascimento: | K1: CPF: | L1: RG: | M1: Expedidor: | N1: Expedição: | O1: Sexo: | P1: Telefone: | Q1: Celular: | R1: Email: | S1: CEP: | T1: Endereco: | U1: Complemento: | V1: Número: | W1: Bairro: | X1: Cidade: | Y1: UF: | Z1: Mãe: | AA1: Pai: | AB1: Apto: | AC1: Cadastrado: | AD1: Alterdado: | AE1: Bloqueio: | AF1: Bloqueado:
A2: =SUBSTITUTE(A1,":","") -> Instituição de ensino | B2: =SUBSTITUTE(B1,":","") -> Turno | C2: =SUBSTITUTE(C1,":","") -> Curso na Intituição | D2: =SUBSTITUTE(D1,":","") -> Grau | E2: =SUBSTITUTE(E1,":","") -> Ano ou Período | F2: =SUBSTITUTE(F1,":","") -> Turma | G2: =SUBSTITUTE(G1,":","") -> Matrícula | H2: =SUBSTITUTE(H1,":","") -> Cartão | ... AF2: =SUBSTITUTE(AF1,":","") -> Bloqueado
A3: =UPPER(A2) -> INSTITUIÇÃO DE ENSINO | B3: =UPPER(B2) -> TURNO | C3: =UPPER(C2) -> CURSO NA INTITUIÇÃO | D3: =UPPER(D2) -> GRAU | E3: =UPPER(E2) -> ANO OU PERÍODO | F3: =UPPER(F2) -> TURMA | G3: =UPPER(G2) -> MATRÍCULA | H3: =UPPER(H2) -> CARTÃO | ... AF3: =UPPER(AF2) -> BLOQUEADO
I4: =SUBSTITUTE(SUBSTITUTE(SUBSTITUTE(SUBSTITUTE(SUBSTITUTE(dados_coletados!Z2, " Da ", " da "), " De ", " de "), " Do ", " do "), " Dos ", " dos "), " Das ", " das ") -> Carliana Lima da Silva | J4: =SUBSTITUTE(SUBSTITUTE(SUBSTITUTE(SUBSTITUTE(SUBSTITUTE(dados_coletados!AA2, " Da ", " da "), " De ", " de "), " Do ", " do "), " Dos ", " dos "), " Das ", " das ") -> Allan Dias de Castro | M4: SUBSTITUIR(SUBSTITUIR(SUBSTITUIR(SUBSTITUIR(dados_coletados!I2; " Da "; " da "); " De "; " de "); " Do "; " do "); " Dos "; " dos ")
I5: =SUBSTITUTE(SUBSTITUTE(SUBSTITUTE(SUBSTITUTE(SUBSTITUTE(dados_coletados!Z3, " Da ", " da "), " De ", " de "), " Do ", " do "), " Dos ", " dos "), " Das ", " das ") -> Andrea Patricia da Silva Estácio | J5: =SUBSTITUTE(SUBSTITUTE(SUBSTITUTE(SUBSTITUTE(SUBSTITUTE(dados_coletados!AA3, " Da ", " da "), " De ", " de "), " Do ", " do "), " Dos ", " dos "), " Das ", " das ") -> Franscisco das Chagas Feitosa
I6: =SUBSTITUTE(SUBSTITUTE(SUBSTITUTE(SUBSTITUTE(SUBSTITUTE(dados_coletados!Z4, " Da ", " da "), " De ", " de "), " Do ", " do "), " Dos ", " dos "), " Das ", " das ") -> Maria Jose do Nascimento Bastos Pinheiro | J6: =SUBSTITUTE(SUBSTITUTE(SUBSTITUTE(SUBSTITUTE(SUBSTITUTE(dados_coletados!AA4, " Da ", " da "), " De ", " de "), " Do ", " do "), " Dos ", " dos "), " Das ", " das ") -> Eduardo dos Santos Pinheiro
I7: =SUBSTITUTE(SUBSTITUTE(SUBSTITUTE(SUBSTITUTE(SUBSTITUTE(dados_coletados!Z5, " Da ", " da "), " De ", " de "), " Do ", " do "), " Dos ", " dos "), " Das ", " das ") -> Dayse Silva do Rosário Abreu | J7: =SUBSTITUTE(SUBSTITUTE(SUBSTITUTE(SUBSTITUTE(SUBSTITUTE(dados_coletados!AA5, " Da ", " da "), " De ", " de "), " Do ", " do "), " Dos ", " dos "), " Das ", " das ") -> Crysthian Gregory Abreu Costa
I8: =SUBSTITUTE(SUBSTITUTE(SUBSTITUTE(SUBSTITUTE(SUBSTITUTE(dados_coletados!Z6, " Da ", " da "), " De ", " de "), " Do ", " do "), " Dos ", " dos "), " Das ", " das ") -> Rafaela Costa do Nascimento | J8: =SUBSTITUTE(SUBSTITUTE(SUBSTITUTE(SUBSTITUTE(SUBSTITUTE(dados_coletados!AA6, " Da ", " da "), " De ", " de "), " Do ", " do "), " Dos ", " dos "), " Das ", " das ") -> Adanias Nogueira
I9: =SUBSTITUTE(SUBSTITUTE(SUBSTITUTE(SUBSTITUTE(SUBSTITUTE(dados_coletados!Z7, " Da ", " da "), " De ", " de "), " Do ", " do "), " Dos ", " dos "), " Das ", " das ") -> Catharina Maria Azevedo Chaves | J9: =SUBSTITUTE(SUBSTITUTE(SUBSTITUTE(SUBSTITUTE(SUBSTITUTE(dados_coletados!AA7, " Da ", " da "), " De ", " de "), " Do ", " do "), " Dos ", " dos "), " Das ", " das ") -> Marcello Carvalho Bittencourt
I10: =SUBSTITUTE(SUBSTITUTE(SUBSTITUTE(SUBSTITUTE(SUBSTITUTE(dados_coletados!Z8, " Da ", " da "), " De ", " de "), " Do ", " do "), " Dos ", " dos "), " Das ", " das ") -> Lindalva Silva Ferreira | J10: =SUBSTITUTE(SUBSTITUTE(SUBSTITUTE(SUBSTITUTE(SUBSTITUTE(dados_coletados!AA8, " Da ", " da "), " De ", " de "), " Do ", " do "), " Dos ", " dos "), " Das ", " das ") -> Roberto Correia Alves
I11: =SUBSTITUTE(SUBSTITUTE(SUBSTITUTE(SUBSTITUTE(SUBSTITUTE(dados_coletados!Z9, " Da ", " da "), " De ", " de "), " Do ", " do "), " Dos ", " dos "), " Das ", " das ") -> Anny Karolynny de Sousa Machado | J11: =SUBSTITUTE(SUBSTITUTE(SUBSTITUTE(SUBSTITUTE(SUBSTITUTE(dados_coletados!AA9, " Da ", " da "), " De ", " de "), " Do ", " do "), " Dos ", " dos "), " Das ", " das ")
I12: =SUBSTITUTE(SUBSTITUTE(SUBSTITUTE(SUBSTITUTE(SUBSTITUTE(dados_coletados!Z10, " Da ", " da "), " De ", " de "), " Do ", " do "), " Dos ", " dos "), " Das ", " das ") -> Aline Figueiredo de Sousa Correa | J12: =SUBSTITUTE(SUBSTITUTE(SUBSTITUTE(SUBSTITUTE(SUBSTITUTE(dados_coletados!AA10, " Da ", " da "), " De ", " de "), " Do ", " do "), " Dos ", " dos "), " Das ", " das ") -> Andre Luis de Jesus Correa
I13: =SUBSTITUTE(SUBSTITUTE(SUBSTITUTE(SUBSTITUTE(SUBSTITUTE(dados_coletados!Z11, " Da ", " da "), " De ", " de "), " Do ", " do "), " Dos ", " dos "), " Das ", " das ") -> Lilia Raquel Matos Guimaraes | J13: =SUBSTITUTE(SUBSTITUTE(SUBSTITUTE(SUBSTITUTE(SUBSTITUTE(dados_coletados!AA11, " Da ", " da "), " De ", " de "), " Do ", " do "), " Dos ", " dos "), " Das ", " das ") -> Uiron Marcos Everton da Silva
I14: =SUBSTITUTE(SUBSTITUTE(SUBSTITUTE(SUBSTITUTE(SUBSTITUTE(dados_coletados!Z12, " Da ", " da "), " De ", " de "), " Do ", " do "), " Dos ", " dos "), " Das ", " das ") -> Carmen Celia Ferreira de Sousa | J14: =SUBSTITUTE(SUBSTITUTE(SUBSTITUTE(SUBSTITUTE(SUBSTITUTE(dados_coletados!AA12, " Da ", " da "), " De ", " de "), " Do ", " do "), " Dos ", " dos "), " Das ", " das ") -> Irandir Araujo Nunes
I15: =SUBSTITUTE(SUBSTITUTE(SUBSTITUTE(SUBSTITUTE(SUBSTITUTE(dados_coletados!Z13, " Da ", " da "), " De ", " de "), " Do ", " do "), " Dos ", " dos "), " Das ", " das ") -> Rayanne Elaine Garcez da Silva | J15: =SUBSTITUTE(SUBSTITUTE(SUBSTITUTE(SUBSTITUTE(SUBSTITUTE(dados_coletados!AA13, " Da ", " da "), " De ", " de "), " Do ", " do "), " Dos ", " dos "), " Das ", " das ") -> Emanuel Monteiro de Lima
I16: =SUBSTITUTE(SUBSTITUTE(SUBSTITUTE(SUBSTITUTE(SUBSTITUTE(dados_coletados!Z14, " Da ", " da "), " De ", " de "), " Do ", " do "), " Dos ", " dos "), " Das ", " das ") -> Keila Nunes Veloso | J16: =SUBSTITUTE(SUBSTITUTE(SUBSTITUTE(SUBSTITUTE(SUBSTITUTE(dados_coletados!AA14, " Da ", " da "), " De ", " de "), " Do ", " do "), " Dos ", " dos "), " Das ", " das ") -> Hugo Deleon Lima de Brito
... I280: =SUBSTITUTE(SUBSTITUTE(SUBSTITUTE(SUBSTITUTE(SUBSTITUTE(dados_coletados!Z278, " Da ", " da "), " De ", " de "), " Do ", " do "), " Dos ", " dos "), " Das ", " das ") -> Deuziane Cardoso Mesquita | J280: =SUBSTITUTE(SUBSTITUTE(SUBSTITUTE(SUBSTITUTE(SUBSTITUTE(dados_coletados!AA278, " Da ", " da "), " De ", " de "), " Do ", " do "), " Dos ", " dos "), " Das ", " das ") -> Gracinaldo Mesquita
I281: =SUBSTITUTE(SUBSTITUTE(SUBSTITUTE(dados_coletados!I279, " Da ", " da "), " De ", " de "), " Do ", " do ")
I282: =SUBSTITUTE(SUBSTITUTE(SUBSTITUTE(dados_coletados!I280, " Da ", " da "), " De ", " de "), " Do ", " do ")
I283: =SUBSTITUTE(SUBSTITUTE(SUBSTITUTE(dados_coletados!I281, " Da ", " da "), " De ", " de "), " Do ", " do ")
I284: =SUBSTITUTE(SUBSTITUTE(SUBSTITUTE(dados_coletados!I282, " Da ", " da "), " De ", " de "), " Do ", " do ")
I285: =SUBSTITUTE(SUBSTITUTE(SUBSTITUTE(dados_coletados!I283, " Da ", " da "), " De ", " de "), " Do ", " do ")
I286: =SUBSTITUTE(SUBSTITUTE(SUBSTITUTE(dados_coletados!I284, " Da ", " da "), " De ", " de "), " Do ", " do ")
I287: =SUBSTITUTE(SUBSTITUTE(SUBSTITUTE(dados_coletados!I285, " Da ", " da "), " De ", " de "), " Do ", " do ")
I288: =SUBSTITUTE(SUBSTITUTE(SUBSTITUTE(dados_coletados!I286, " Da ", " da "), " De ", " de "), " Do ", " do ")
I289: =SUBSTITUTE(SUBSTITUTE(SUBSTITUTE(dados_coletados!I287, " Da ", " da "), " De ", " de "), " Do ", " do ")
I290: =SUBSTITUTE(SUBSTITUTE(SUBSTITUTE(dados_coletados!I288, " Da ", " da "), " De ", " de "), " Do ", " do ")
I291: =SUBSTITUTE(SUBSTITUTE(SUBSTITUTE(dados_coletados!I289, " Da ", " da "), " De ", " de "), " Do ", " do ")
I292: =SUBSTITUTE(SUBSTITUTE(SUBSTITUTE(dados_coletados!I290, " Da ", " da "), " De ", " de "), " Do ", " do ")
... I431: =SUBSTITUTE(SUBSTITUTE(SUBSTITUTE(dados_coletados!I429, " Da ", " da "), " De ", " de "), " Do ", " do ")
